Workbook

Sheet Общее, домены, поддомены

Sheet Результаты аудита
F1: Уровень сложности практики | O1: Инструкция по заполнению описана в репозитории проекта на Github
B2: Модель | C2: Домен | D2: Описание поддомена | E2: Поддомен | F2: 0. Uninitiated | G2: 1. Beginners | H2: 2. Intermediate | I2: 3. Advanced | J2: 4. Experts | K2: % выполнения всех практик кажого ПОДдомена DAF | L2: % выполнения всех практик кажого домена DAF | M2: % выполнения всех практик всего DAF | O2: Уровни Кирилламиды | Q2: % соответствия уровню зрелости по Кирилламиде | R2: Итоговый уровень зрелости Компании (из 7 возможных) по DAF
B3: Технологии | C3: Контроль ИБ артефактов, зависимостей и образов | D3: Контроль использования сторонних компонентов | E3: T-ADI-DEP | F3: =IF(Практики!F3="Неверно","Не реализовывается","Реализовывается") -> Реализовывается | G3: =Практики!H4 -> 0 | H3: =Практики!H9 -> 0 | I3: =Практики!H11 -> 0 | J3: =Практики!H14 -> 0 | K3: =SUM(G3:J3)/4 -> 0 | L3: =AVERAGE(K3:K4) -> 0 | M3: =AVERAGE(K3:K42) -> 0 | O3: 0 | P3: Хаос | Q3: =Кирилламида!B86 -> 0 | R3: =R42 -> 0
D4: Управление артефактами | E4: T-ADI-ART | F4: =IF(Практики!F16="Неверно","Не реализовывается","Реализовывается") -> Реализовывается | G4: =Практики!H17 -> 0 | H4: =Практики!H22 -> 0 | I4: =Практики!H24 -> 0 | J4: =Практики!H26 -> 0 | K4: =SUM(G4:J4)/4 -> 0 | O4: 1 | P4: Минимальный | Q4: =Кирилламида!C86 -> 0
C5: Защита окружения разработки | D5: Защита рабочих мест разработчика | E5: T-DEV-COMP | F5: =IF(Практики!F32="Неверно","Не реализовывается","Реализовывается") -> Реализовывается | G5: =Практики!H33 -> 0 | H5: =Практики!H35 -> 0 | K5: =SUM(G5:H5)/2 -> 0 | L5: =AVERAGE(K5:K10) -> 0 | O5: 2 | P5: Базовый | Q5: =Кирилламида!D86 -> 0
D6: Защита секретов | E6: T-DEV-SM | F6: =IF(Практики!F36="Неверно","Не реализовывается","Реализовывается") -> Реализовывается | G6: =Практики!H37 -> 0 | H6: =Практики!H39 -> 0 | I6: =Практики!H41 -> 0 | J6: =Практики!H43 -> 0 | K6: =SUM(G6:J6)/4 -> 0 | O6: 3 | P6: Повышенный | Q6: =Кирилламида!E86 -> 0
D7: Защита Build-среды | E7: T-DEV-BLD | F7: =IF(Практики!F44="Неверно","Не реализовывается","Реализовывается") -> Реализовывается | G7: =Практики!H45 -> 0 | H7: =Практики!H49 -> 0 | I7: =Практики!H50 -> 0 | J7: =Практики!H53 -> 0 | K7: =SUM(G7:J7)/4 -> 0 | O7: 4 | P7: Продвинутый | Q7: =Кирилламида!F86 -> 0
D8: Защита source code management (SCM) | E8: T-DEV-SCM | F8: =IF(Практики!F54="Неверно","Не реализовывается","Реализовывается") -> Реализовывается | G8: =Практики!H55 -> 0 | H8: =Практики!H62 -> 0 | I8: =Практики!H68 -> 0 | J8: =Практики!H72 -> 0 | K8: =SUM(G8:J8)/4 -> 0 | O8: 5 | P8: Развитый | Q8: =Кирилламида!G86 -> 0
D9: Контроль внесения изменений в исходный код | E9: T-DEV-SRC | F9: =IF(Практики!F75="Неверно","Не реализовывается","Реализовывается") -> Реализовывается | G9: =Практики!H76 -> 0 | H9: =Практики!H81 -> 0 | I9: =Практики!H87 -> 0 | J9: =Практики!H93 -> 0 | K9: =SUM(G9:J9)/4 -> 0 | O9: 6 | P9: Экспертный | Q9: =Кирилламида!H86 -> 0
D10: Защита конвейера сборки | E10: T-DEV-CICD | F10: =IF(Практики!F94="Неверно","Не реализовывается","Реализовывается") -> Реализовывается | G10: =Практики!H95 -> 0 | H10: =Практики!H100 -> 0 | I10: =Практики!H102 -> 0 | J10: =Практики!H103 -> 0 | K10: =SUM(G10:J10)/4 -> 0 | O10: 7 | P10: Космический | Q10: =Кирилламида!I86 -> 0
C11: Инструментальный анализ на наличие дефектов ИБ | D11: Безопасность заказной разработки | E11: T-CODE-SPC | F11: =IF(Практики!F106="Неверно","Не реализовывается","Реализовывается") -> Реализовывается | G11: =Практики!H107 -> 0 | H11: =Практики!H109 -> 0 | I11: =Практики!H113 -> 0 | J11: =Практики!H118 -> 0 | K11: =SUM(G11:J11)/4 -> 0 | L11: =AVERAGE(K11:K16) -> 0
D12: Статический анализ (SAST) | E12: T-CODE-SST | F12: =IF(Практики!F119="Неверно","Не реализовывается","Реализовывается") -> Реализовывается | G12: =Практики!H120 -> 0 | H12: =Практики!H122 -> 0 | I12: =Практики!H126 -> 0 | J12: =Практики!H129 -> 0 | K12: =SUM(G12:J12)/4 -> 0
D13: Композиционный анализ (SCA) | E13: T-CODE-SC | F13: =IF(Практики!F130="Неверно","Не реализовывается","Реализовывается") -> Реализовывается | G13: =Практики!H131 -> 0 | H13: =Практики!H134 -> 0 | I13: =Практики!H139 -> 0 | J13: =Практики!H143 -> 0 | K13: =SUM(G13:J13)/4 -> 0
D14: Анализ образов контейнеров | E14: T-CODE-IMG | F14: =IF(Практики!F144="Неверно","Не реализовывается","Реализовывается") -> Реализовывается | G14: =Практики!H145 -> 0 | H14: =Практики!H148 -> 0 | I14: =Практики!H151 -> 0 | J14: =Практики!H152 -> 0 | K14: =SUM(G14:J14)/4 -> 0
D15: Идентификация секретов | E15: T-CODE-SECDN | F15: =IF(Практики!F154="Неверно","Не реализовывается","Реализовывается") -> Реализовывается | G15: =Практики!H155 -> 0 | H15: =Практики!H159 -> 0 | I15: =Практики!H162 -> 0 | J15: =Практики!H165 -> 0 | K15: =SUM(G15:J15)/4 -> 0
D16: Контроль безопасности Dockerfile’ов | E16: T-CODE-DOCKERFS | F16: =IF(Практики!F166="Неверно","Не реализовывается","Реализовывается") -> Реализовывается | G16: =Практики!H167 -> 0 | H16: =Практики!H169 -> 0 | K16: =SUM(G16:H16)/2 -> 0
C17: Анализ ПО в режиме runtime - Preprod | D17: Динамический анализ приложений (DAST) в PREPROD среде | E17: T-PREPROD-DAST | F17: =IF(Практики!F172="Неверно","Не реализовывается","Реализовывается") -> Реализовывается | G17: =Практики!H173 -> 0 | H17: =Практики!H175 -> 0 | I17: =Практики!H179 -> 0 | J17: =Практики!H183 -> 0 | K17: =SUM(G17:J17)/4 -> 0 | L17: =AVERAGE(K17:K21) -> 0
D18: Тестирование на проникновение перед внедрением приложений в продуктив | E18: T-PREPROD-PENTEST | F18: =IF(Практики!F186="Неверно","Не реализовывается","Реализовывается") -> Реализовывается | G18: =Практики!H187 -> 0 | H18: =Практики!H190 -> 0 | J18: =Практики!H191 -> 0 | K18: =SUM(G18:J18)/3 -> 0
D19: Функциональное ИБ-тестирование | E19: T-PREPROD-SECTEST | F19: =IF(Практики!F192="Неверно","Не реализовывается","Реализовывается") -> Реализовывается | G19: =Практики!H193 -> 0 | H19: =Практики!H194 -> 0 | I19: =Практики!H196 -> 0 | K19: =SUM(G19:I19)/3 -> 0
D20: Контроль безопасности манифестов (k8s, terraform и т.д.) | E20: T-PREPROD-MANSEC | F20: =IF(Практики!F209="Неверно","Не реализовывается","Реализовывается") -> Реализовывается | G20: =Практики!H210 -> 0 | H20: =Практики!H211 -> 0 | K20: =SUM(G20:H20)/2 -> 0
D21: Анализ инфраструктуры PREPROD среды на уязвимости | E21: T-PREPROD-VULN | F21: =IF(Практики!F197="Неверно","Не реализовывается","Реализовывается") -> Реализовывается | G21: =Практики!H198 -> 0 | H21: =Практики!H200 -> 0 | I21: =Практики!H203 -> 0 | J21: =Практики!H207 -> 0 | K21: =SUM(G21:J21)/4 -> 0
C22: Защита ПО и инфраструктуры в режиме runtime | D22: Управление секретами | E22: T-PROD-SM | F22: =IF(Практики!F214="Неверно","Не реализовывается","Реализовывается") -> Реализовывается | G22: =Практики!H215 -> 0 | H22: =Практики!H217 -> 0 | I22: =Практики!H219 -> 0 | J22: =Практики!H222 -> 0 | K22: =SUM(G22:J22)/4 -> 0 | L22: =AVERAGE(K22:K29) -> 0
D23: Динамический анализ приложений (DAST) в продуктивной среде | E23: T-PROD-DAST | F23: =IF(Практики!F233="Неверно","Не реализовывается","Реализовывается") -> Реализовывается | G23: =Практики!H234 -> 0 | H23: =Практики!H237 -> 0 | I23: =Практики!H241 -> 0 | J23: =Практики!H245 -> 0 | K23: =SUM(G23:J23)/4 -> 0
D24: Тестирование на проникновение продуктивной среды | E24: T-PROD-PENTEST | F24: =IF(Практики!F225="Неверно","Не реализовывается","Реализовывается") -> Реализовывается | G24: =Практики!H226 -> 0 | H24: =Практики!H229 -> 0 | I24: =Практики!H230 -> 0 | J24: =Практики!H231 -> 0 | K24: =SUM(G24:J24)/4 -> 0
D25: Управление изменениями инфраструктуры и доступом к ней | E25: T-PROD-ACCESS | F25: =IF(Практики!F248="Неверно","Не реализовывается","Реализовывается") -> Реализовывается | G25: =Практики!H249 -> 0 | H25: =Практики!H254 -> 0 | I25: =Практики!H256 -> 0 | J25: =Практики!H257 -> 0 | K25: =SUM(G25:J25)/4 -> 0
D26: Контроль сетевого трафика (L4-L7) | E26: T-PROD-NETWORK | F26: =IF(Практики!F258="Неверно","Не реализовывается","Реализовывается") -> Реализовывается | G26: =Практики!H259 -> 0 | H26: =Практики!H261 -> 0 | I26: =Практики!H263 -> 0 | K26: =SUM(G26:I26)/3 -> 0
D27: Контроль выполняемых и процессов и их прав доступа | E27: T-PROD-RUN | F27: =IF(Практики!F264="Неверно","Не реализовывается","Реализовывается") -> Реализовывается | G27: =Практики!H265 -> 0 | H27: =Практики!H266 -> 0 | I27: =Практики!H267 -> 0 | K27: =SUM(G27:I27)/3 -> 0
D28: Анализ инфраструктуры PROD среды на уязвимости | E28: T-PROD-VULN | F28: =IF(Практики!F268="Неверно","Не реализовывается","Реализовывается") -> Реализовывается | G28: =Практики!H269 -> 0 | H28: =Практики!H271 -> 0 | I28: =Практики!H274 -> 0 | J28: =Практики!H278 -> 0 | K28: =SUM(G28:J28)/4 -> 0
D29: Анализ событий информационной безопасности | E29: T-PROD-EVENTS | F29: =IF(Практики!F280="Неверно","Не реализовывается","Реализовывается") -> Реализовывается | H29: =Практики!H281 -> 0 | I29: =Практики!H282 -> 0 | K29: =SUM(H29:I29)/2 -> 0
B30: Процессы | C30: Обучение и база знаний | D30: Обучение специалистов | E30: P-EDU-AWR | F30: =IF(Практики!F285="Неверно","Не реализовывается","Реализовывается") -> Реализовывается | G30: =Практики!H286 -> 0 | H30: =Практики!H288 -> 0 | I30: =Практики!H292 -> 0 | J30: =Практики!H294 -> 0 | K30: =SUM(G30:J30)/4 -> 0 | L30: =AVERAGE(K30:K31) -> 0
D31: Управление базой знаний DSO | E31: P-EDU-KB | F31: =IF(Практики!F295="Неверно","Не реализовывается","Реализовывается") -> Реализовывается | G31: =Практики!H296 -> 0 | H31: =Практики!H297 -> 0 | I31: =Практики!H299 -> 0 | J31: =Практики!H302 -> 0 | K31: =SUM(G31:J31)/4 -> 0
C32: Контроль и формирование требований ИБ к ПО | D32: Оценка критичности приложений и моделирование угроз | E32: P-REQ-TM | F32: =IF(Практики!F306="Неверно","Не реализовывается","Реализовывается") -> Реализовывается | G32: =Практики!H307 -> 0 | H32: =Практики!H310 -> 0 | I32: =Практики!H313 -> 0 | J32: =Практики!H316 -> 0 | K32: =SUM(G32:J32)/4 -> 0 | L32: =AVERAGE(K32:K36) -> 0
D33: Определение требований ИБ, предъявляемых к ПО | E33: P-REQ-RD | F33: =IF(Практики!F317="Неверно","Не реализовывается","Реализовывается") -> Реализовывается | G33: =Практики!H318 -> 0 | H33: =Практики!H320 -> 0 | I33: =Практики!H323 -> 0 | J33: =Практики!H326 -> 0 | K33: =SUM(G33:J33)/4 -> 0
D34: Контроль выполнения требований ИБ | E34: P-REQ-CR | F34: =IF(Практики!F327="Неверно","Не реализовывается","Реализовывается") -> Реализовывается | G34: =Практики!H328 -> 0 | H34: =Практики!H329 -> 0 | I34: =Практики!H330 -> 0 | J34: =Практики!H331 -> 0 | K34: =SUM(G34:J34)/4 -> 0 | O34: Порог выполнения ("прохождения") уровня каждого уровня DAF | R34: 0.8
D35: Разработка стандартов конфигураций разрабатываемого ПО | E35: P-REQ-STDR-App | F35: =IF(Практики!F332="Неверно","Не реализовывается","Реализовывается") -> Реализовывается | G35: =Практики!H333 -> 0 | H35: =Практики!H335 -> 0 | I35: =Практики!H336 -> 0 | J35: =Практики!H338 -> 0 | K35: =SUM(G35:J35)/4 -> 0
D36: Разработка стандартов конфигураций для компонентов инфраструктуры | E36: P-REQ-STDR-Infr | F36: =IF(Практики!F339="Неверно","Не реализовывается","Реализовывается") -> Реализовывается | G36: =Практики!H340 -> 0 | H36: =Практики!H342 -> 0 | I36: =Практики!H344 -> 0 | J36: =Практики!H347 -> 0 | K36: =SUM(G36:J36)/4 -> 0 | O36: Согласно методике DAF уровень зрелости присваивается, если выполнено два ОБЯЗАТЕЛЬНЫХ условия: "Выполнено не менее 80% практик уровня Кирилламиды" И (!!!) "все предыдущие уровни зрелости выполнены не менее чем на 80%" Примечание к формулам расчета справа: 1. Сначала определяем закрыт ли каждый из уровней "Хаос" (уровень 0) И "Минимальный" (уровень 1) не менее чем на 80% (ячейкаR37). Если оба закрыты, то присваиваем уровень 1, если нет - уровень 0 2. Затем определяем закрыт ли уровень "Базовый" на 80 и более %. Если да - присваиваем уровень 2, если нет - смотрим значение ячейки R37 3. Затем определяем закрыт ли уровень "Повышенный" на 80 и более %. Если да - присваиваем уровень 3, если нет - смотрим значение ячейки R38 4. итд | R36: =IF(AND(Q3>=R34, Q4>=R34),1,0) -> 0
C37: Управление ИБ дефектами | D37: Обработка дефектов ИБ | E37: P-DEFECT-MNG | F37: =IF(Практики!F350="Неверно","Не реализовывается","Реализовывается") -> Реализовывается | G37: =Практики!H351 -> 0 | H37: =Практики!H352 -> 0 | I37: =Практики!H354 -> 0 | J37: =Практики!H357 -> 0 | K37: =SUM(G37:J37)/4 -> 0 | L37: =AVERAGE(K37:K38) -> 0 | R37: =IF(AND(R36=1,Q5>=R34),2,R36) -> 0
D38: Консолидация дефектов ИБ | E38: P-DEFECT-CNS | F38: =IF(Практики!F358="Неверно","Не реализовывается","Реализовывается") -> Реализовывается | G38: =Практики!H359 -> 0 | H38: =Практики!H361 -> 0 | I38: =Практики!H362 -> 0 | J38: =Практики!H365 -> 0 | K38: =SUM(G38:J38)/4 -> 0 | R38: =IF(AND(R37=2,Q6>=R34),3,R37) -> 0
C39: Оценка эффективности процессов | D39: Управление набором метрик ИБ | E39: P-MET-SET | F39: =IF(Практики!F368="Неверно","Не реализовывается","Реализовывается") -> Реализовывается | H39: =Практики!H369 -> 0 | I39: =Практики!H371 -> 0 | K39: =SUM(H39:I39)/2 -> 0 | L39: =AVERAGE(K39:K40) -> 0 | R39: =IF(AND(R38=3,Q7>=R34),4,R38) -> 0
D40: Контроль исполнения метрик | E40: P-MET-EX | F40: =IF(Практики!F373="Неверно","Не реализовывается","Реализовывается") -> Реализовывается | H40: =Практики!H374 -> 0 | I40: =Практики!H376 -> 0 | J40: =Практики!H379 -> 0 | K40: =SUM(H40:J40)/3 -> 0 | R40: =IF(AND(R39=4,Q8>=R34),5,R39) -> 0
...

Sheet Практики
B1: Поддомен | C1: ID | D1: Практики и их требования | E1: Область действия практики | F1: Оценка | G1: Уровень сложности практики | H1: Соответствие уровню сложности | I1: % выполнения группы практик | J1: Уровень Кирилламиды | K1: BSIMM v14 | L1: DSOMM | M1: OWASP SAMMv2 | N1: ПЗ ЦБ | O1: ГОСТ Р 56939 | P1: AppSec Table Top (Positive) | Q1: Комментарии
B2: Домен "Контроль ИБ артефактов, зависимостей и образов"
B3: ='Результаты аудита'!D3 -> Контроль использования сторонних компонентов | C3: T-ADI-DEP-0-1 | D3: Управление зависимостями (Dependencies) в исходном коде осуществляется в каком-либо виде | E3: Отдельная команда | F3: Не заполнено | G3: 0 | H3: =(COUNTIF(F3:F3,$F$407))/COUNTA(F3:F3) -> 0 | I3: =SUM(H4:H15)/4 -> 0 | J3: 0 | L3: 4 | M3: SB-B-1
C4: T-ADI-DEP-1-1 | D4: Существуют (формализованы) единые правила, определяющие возможность использования тех или иных зависимостей в коде. Например, есть утвержденный документ, и/или страница в базе знаний, описывающие порядок использования зависимостей в коде. | E4: Отдельная команда | F4: Не заполнено | G4: 1 | H4: =(COUNTIF(F4:F8,$G$409)+(COUNTIF(F4:F8,$G$408)*0.5))/(COUNTA(F4:F8)-COUNTIF(F4:F8,$G$410)) -> 0 | J4: 2 | M4: SB-B-2 | N4: 7.4.2.1 | P4: TP2
C5: T-ADI-DEP-1-2 | D5: Обновление существующих зависимостей выполняется вручную. Например, если возникла необходимость использовать новую версию библиотеки в коде, то ее вручную выгружают и добавляют в проект | E5: Отдельная команда | F5: Не заполнено | J5: 2 | L5: 9 | M5: SB-B-2
C6: T-ADI-DEP-1-3 | D6: Существует (описан, формализован) план реагирования на события ИБ, связанных с зависимостями. | E6: Отдельная команда | F6: Не заполнено | J6: 2 | K6: SR2.7 | N6: 7.4.2.1 | O6: 5.16.2.1 | P6: MI4
C7: T-ADI-DEP-1-4 | D7: Выполняется харденинг (безопасная настройка) файлов конфигураций используемых пакетов open source software - OSS (например, nuget.config, .npmrc, pip.conf, pom.xml, etc.). | E7: Отдельная команда | F7: Не заполнено | J7: 2 | L7: 83 91 56 | M7: EM-A-1 | P7: CNFG1
C8: T-ADI-DEP-1-5 | D8: Зависимости с тэгом "latest" не применяются | E8: Отдельная команда | F8: Не заполнено | J8: 2 | M8: SA-B-1
C9: T-ADI-DEP-2-1 | D9: Разработчики получают и используют OSS компоненты, применяя только стандартизованные (формализованные и утвержденные) методы | E9: Отдельная команда | F9: Не заполнено | G9: 2 | H9: =(COUNTIF(F9:F10,$G$409)+(COUNTIF(F9:F10,$G$408)*0.5))/(COUNTA(F9:F10)-COUNTIF(F9:F10,$G$410)) -> 0 | J9: 3 | K9: SR2.7 | N9: 7.4.2.1, 7.4.3.7 Табл. 5 - Анализ кода, компонентов на соответствие ИБ
C10: T-ADI-DEP-2-2 | D10: Контролируется и регулируется использование новых (моложе 60 дней) и старых (неактуальных, заброшенных, старше 365 дней) OSS. Например, настроен OSS firewall на предупреждение (или запрет) использования OSS, выпущенных\актуализированных более 365 дней назад и менее чем 60 дней | E10: Отдельная команда | F10: Не заполнено | J10: 3 | M10: OM-B-1 OM-B-2 SB-B-2 | N10: 7.4.3.6 Табл. 4 - Проверка соответствия требованиям ИБ стороннего программного обеспечения
C11: T-ADI-DEP-3-1 | D11: Выполняется инвентаризация используемых зависимостей. Например, создан внутренний репозиторий. | E11: Отдельная команда | F11: Не заполнено | G11: 3 | H11: =(COUNTIF(F11:F13,$G$409)+(COUNTIF(F11:F13,$G$408)*0.5))/(COUNTA(F11:F13)-COUNTIF(F11:F13,$G$410)) -> 0 | J11: 4 | K11: SR1.5 | M11: SB-B-1 | N11: 7.4.3.7 Табл. 5 - Анализ кода, компонентов на соответствие ИБ | O11: 5.16.2.2 | P11: SCA5
C12: T-ADI-DEP-3-2 | D12: При выполнении запросов на слияние (PR/MR) предоставляется список всех уязвимостей используемых зависимостей. Это может быть реализовано с помощью SCA решения | E12: Отдельная команда | F12: Не заполнено | J12: 4 | N12: 7.4.3.7 Табл. 5 - Анализ коммерческих и открытых программных модулей на наличие уязвимостей
C13: T-ADI-DEP-3-3 | D13: Выполняется автоматическое обновление используемых зависимостей. Это может быть реализовано с помощью специальных утилит для обновления зависимостей. | E13: Отдельная команда | F13: Не заполнено | J13: 4 | L13: 10
C14: T-ADI-DEP-4-1 | D14: Выполняется верификация цифровой подписи SBOM перед использованием зависимостей в сборке. Это может быть реализовано с помощью SCA решения | E14: Отдельная команда | F14: Не заполнено | G14: 4 | H14: =(COUNTIF(F14:F15,$G$409)+(COUNTIF(F14:F15,$G$408)*0.5))/(COUNTA(F14:F15)-COUNTIF(F14:F15,$G$410)) -> 0 | J14: 6 | P14: SCS1 IA3
C15: T-ADI-DEP-4-2 | D15: Выполняется самостоятельная сборка необходимых зависимостей в доверенной среде | E15: Отдельная команда | F15: Не заполнено | J15: 6
B16: ='Результаты аудита'!D4 -> Управление артефактами | C16: T-ADI-ART-0-1 | D16: Управление артефактами разработки присутствует в каком-либо виде | E16: Отдельная команда | F16: Не заполнено | G16: 0 | H16: =(COUNTIF(F16:F16,$F$407))/COUNTA(F16:F16) -> 0 | I16: =SUM(H17:H29)/4 -> 0 | J16: 0 | M16: SA-B-2
C17: T-ADI-ART-1-1 | D17: Все артефакты разработки хранятся в доверенных registry. Например, используется внутренний реестр. | E17: Отдельная команда | F17: Не заполнено | G17: 1 | H17: =(COUNTIF(F17:F21,$G$409)+(COUNTIF(F17:F21,$G$408)*0.5))/(COUNTA(F17:F21)-COUNTIF(F17:F21,$G$410)) -> 0 | J17: 1 | N17: 7.4.3.3 | O17: 5.13.2.5 | P17: OSS2
C18: T-ADI-ART-1-2 | D18: Строго ограниченный перечень лиц может помещать артефакты в registry. Внутри registry настроены правила разграничения доступа. | E18: Отдельная команда | F18: Не заполнено | J18: 1 | L18: 60 58 57 | O18: 5.13.2.2 | P18: AC2
C19: T-ADI-ART-1-3 | D19: Для аутентификации в registry используются внешние сервисы. Например, выполнена интеграция с LDAP или другим IdM, локальные учетные записи не используются. | E19: Отдельная команда | F19: Не заполнено | J19: 1 | L19: 60 59
C20: T-ADI-ART-1-4 | D20: Отключен анонимный доступ в registry | E20: Отдельная команда | F20: Не заполнено | J20: 1 | P20: AC2 CNFG1
C21: T-ADI-ART-1-5 | D21: Настроен и включен аудит любых изменений конфигурации хранилищ артефактов | E21: Отдельная команда | F21: Не заполнено | J21: 1 | L21: 108 106 101 | P21: CNFG1
C22: T-ADI-ART-2-1 | D22: Разработчики получают артефакты для дальнейшей работы только из внутренних репозиториев | E22: Отдельная команда | F22: Не заполнено | G22: 2 | H22: =(COUNTIF(F22:F23,$G$409)+(COUNTIF(F22:F23,$G$408)*0.5))/(COUNTA(F22:F23)-COUNTIF(F22:F23,$G$410)) -> 0 | J22: 3 | N22: 7.4.3.7 Табл. 5 - Анализ кода, компонентов на соответствие ИБ
C23: T-ADI-ART-2-2 | D23: Для взаимодействия с registry используются webhook с использованием TLS версии не ниже 1.2 | E23: Отдельная команда | F23: Не заполнено | J23: 3
C24: T-ADI-ART-3-1 | D24: Для всех артефактов создается SBOM | E24: Отдельная команда | F24: Не заполнено | G24: 3 | H24: =(COUNTIF(F24:F25,$G$409)+(COUNTIF(F24:F25,$G$408)*0.5))/(COUNTA(F24:F25)-COUNTIF(F24:F25,$G$410)) -> 0 | J24: 4 | K24: SR1.5 SE3.6 | L24: 4 | O24: 5.16.2.2
C25: T-ADI-ART-3-2 | D25: Используется многофакторная аутентификация для доступа к registry | E25: Отдельная команда | F25: Не заполнено | J25: 4 | L25: 60 59
C26: T-ADI-ART-4-1 | D26: Конвейер сборки (build pipeline) подписывает все артефакты, которые он создает | E26: Отдельная команда | F26: Не заполнено | G26: 4 | H26: =(COUNTIF(F26:F29,$G$409)+(COUNTIF(F26:F29,$G$408)*0.5))/(COUNTA(F26:F29)) -> 0 | J26: 5 | K26: SE2.4 | P26: IA3
C27: T-ADI-ART-4-2 | D27: Выполняется шифрование всех артефактов в registry | E27: Отдельная команда | F27: Не заполнено | G27: 4 | J27: 5
C28: T-ADI-ART-4-3 | D28: Выполняется создание цифровых подписей артефактов после проверок безопасности и перед их отправкой в доверенный registry | E28: Отдельная команда | F28: Не заполнено | G28: 4 | J28: 5 | K28: SE2.4 | P28: SCS1 IA3
C29: T-ADI-ART-4-4 | D29: Выполняется создание хэш сумм артефактов перед отправкой их в registry, а также их проверка при сборке | E29: Отдельная команда | F29: Не заполнено | G29: 4 | J29: 5 | N29: 7.4.3.7 Табл. 5 - Обеспечение контроля целостности всего программного кода и размещение доступных механизмов для контроля в соответствующих средах | P29: SCS1 IA3
B31: Домен "Защита окружения разработки"
B32: ='Результаты аудита'!D5 -> Защита рабочих мест разработчика | C32: T-DEV-COMP-0-1 | D32: Применяются практики защиты рабочих мест разработчиков | E32: Отдельная команда | F32: Не заполнено | G32: 0 | H32: =(COUNTIF(F32:F32,$F$407))/COUNTA(F32:F32) -> 0 | I32: =SUM(H33:H35)/2 -> 0 | J32: 0 | N32: 7.4.3.2 | P32: CNFG1 MI1
C33: T-DEV-COMP-1-1 | D33: Утверждены и применяются базовые требования к ПО и настройкам на корпоративных рабочих местах разработчиков. Например, требования к антивирусу, обновлениям ОС, требования к паролям. | E33: Отдельная команда | F33: Не заполнено | G33: 1 | H33: =(COUNTIF(F33:F34,$G$409)+(COUNTIF(F33:F34,$G$408)*0.5))/(COUNTA(F33:F34)-COUNTIF(F33:F34,$G$410)) -> 0 | J33: 1 | N33: 7.4.3.2
C34: T-DEV-COMP-1-2 | D34: Удаленный доступ с некорпоративных (и, соответственно, ненастроенных) устройств к инструментам разработки возможен только для ограниченного (небольшого) числа устройств. | E34: Отдельная команда | F34: Не заполнено | J34: 1 | N34: 7.4.3.2 | P34: AC2 MI1
C35: T-DEV-COMP-2-1 | D35: Удаленный доступ к инструментам разработки возможен либо с корпоративных устройств с использованием MDM, либо через промежуточные\проксирующие системы, например, VDI или PAM. | E35: Отдельная команда | F35: Не заполнено | G35: 2 | H35: =(COUNTIF(F35,$G$409)+(COUNTIF(F35,$G$408)*0.5))/COUNTA(F35) -> 0 | J35: 3 | N35: 7.4.3.2 | P35: MI1
B36: ='Результаты аудита'!D6 -> Защита секретов | C36: T-DEV-SM-0-1 | D36: Существует практика управления секретами | E36: Отдельная команда | F36: Не заполнено | G36: 0 | H36: =(COUNTIF(F36:F36,$F$407))/COUNTA(F36:F36) -> 0 | I36: =SUM(H37:H43)/4 -> 0 | J36: 0 | L36: 7 | M36: SD-B-1 | O36: 5.15.2.2
C37: T-DEV-SM-1-1 | D37: Секреты в среде разработки защищаются встроенными механизмами инструментов разработки, например, CI/CD системы, без применения Secret Management систем. | E37: Отдельная команда | F37: Не заполнено | G37: 1 | H37: =(COUNTIF(F37:F38,$G$409)+(COUNTIF(F37:F38,$G$408)*0.5))/(COUNTA(F37:F38)-COUNTIF(F37:F38,$G$410)) -> 0 | J37: 1 | L37: 7 | M37: SD-B-1
C38: T-DEV-SM-1-2 | D38: Инциденты ИБ, связанные с использованием секретов в среде разработки, обрабатываются службой ИБ совместно с разработчиками. | E38: Отдельная команда | F38: Не заполнено | J38: 1 | K38: CMVM1.1 | M38: IM-A-2 | P38: MI4
C39: T-DEV-SM-2-1 | D39: Секреты окружения разработки хранятся в Secret Management инструменте, например, Hashicorp Vault. | E39: Отдельная команда | F39: Не заполнено | G39: 2 | H39: =(COUNTIF(F39:F40,$G$409)+(COUNTIF(F39:F40,$G$408)*0.5))/(COUNTA(F39:F40)-COUNTIF(F39:F40,$G$410)) -> 0 | J39: 2 | L39: 7 | M39: SD-B-2 | O39: 5.15.2.4 | P39: IA2
C40: T-DEV-SM-2-2 | D40: Разработчики и инженеры обмениваются секретами с помощью инструмента Secret Management, например, Hashicorp Vault | E40: Отдельная команда | F40: Не заполнено | J40: 2 | M40: SD-B-2 | O40: 5.15.2.4
C41: T-DEV-SM-3-1 | D41: Секреты всех сред и инструментов (за исключением рабочих станций разработчиков и подобных adhoc сред) хранятся в SM (например, Vault), количество hardcoded секретов минимально. Случаи использования hardcoded секретов известны команде ИБ и запланирован отказ от их использования | E41: Отдельная команда | F41: Не заполнено | G41: 3 | H41: =(COUNTIF(F41:F42,$G$409)+(COUNTIF(F41:F42,$G$408)*0.5))/(COUNTA(F41:F42)-COUNTIF(F41:F42,$G$410)) -> 0 | J41: 3 | L41: 7 | M41: SD-B-1
...

Sheet Кирилламида
A1: Уровни зрелости. Расположение групп практик
B2: 0. Хаос | C2: 1. Минимальный | D2: 2. Базовый | E2: 3. Повышенный | F2: 4. Продвинутый | G2: 5. Развитый | H2: 6. Экспертный | I2: 7. Космический
A3: ='Результаты аудита'!E3 -> T-ADI-DEP | B3: T-ADI-DEP-0 | D3: T-ADI-DEP-1 | E3: T-ADI-DEP-2 | F3: T-ADI-DEP-3 | H3: T-ADI-DEP-4
A4: ='Результаты аудита'!E4 -> T-ADI-ART | B4: T-ADI-ART-0 | C4: T-ADI-ART-1 | E4: T-ADI-ART-2 | F4: T-ADI-ART-3 | G4: T-ADI-ART-4
A5: ='Результаты аудита'!E5 -> T-DEV-COMP | B5: T-DEV-COMP-0 | C5: T-DEV-COMP-1 | E5: T-DEV-COMP-2
A6: ='Результаты аудита'!E6 -> T-DEV-SM | B6: T-DEV-SM-0 | C6: T-DEV-SM-1 | D6: T-DEV-SM-2 | E6: T-DEV-SM-3 | H6: T-DEV-SM-4
A7: ='Результаты аудита'!E7 -> T-DEV-BLD | B7: T-DEV-BLD-0 | D7: T-DEV-BLD-1 | E7: T-DEV-BLD-2 | G7: T-DEV-BLD-3 | H7: T-DEV-BLD-4
A8: ='Результаты аудита'!E8 -> T-DEV-SCM | B8: T-DEV-SCM-0 | D8: T-DEV-SCM-1 | E8: T-DEV-SCM-2 | F8: T-DEV-SCM-3 | H8: T-DEV-SCM-4
A9: ='Результаты аудита'!E9 -> T-DEV-SRC | B9: T-DEV-SRC-0 | C9: T-DEV-SRC-1 | E9: T-DEV-SRC-2 | F9: T-DEV-SRC-3 | H9: T-DEV-SRC-4
A10: ='Результаты аудита'!E10 -> T-DEV-CICD | B10: T-DEV-CICD-0 | C10: T-DEV-CICD-1 | E10: T-DEV-CICD-2 | F10: T-DEV-CICD-3 | G10: T-DEV-CICD-4
A11: ='Результаты аудита'!E11 -> T-CODE-SPC | B11: T-CODE-SPC-0 | D11: T-CODE-SPC-1 | F11: T-CODE-SPC-2 | G11: T-CODE-SPC-3 | I11: T-CODE-SPC-4
A12: ='Результаты аудита'!E12 -> T-CODE-SST | B12: T-CODE-SST-0 | D12: T-CODE-SST-1 | E12: T-CODE-SST-2 | F12: T-CODE-SST-3 | I12: T-CODE-SST-4
A13: ='Результаты аудита'!E13 -> T-CODE-SC | B13: T-CODE-SC-0 | C13: T-CODE-SC-1 | D13: T-CODE-SC-2 | F13: T-CODE-SC-3 | H13: T-CODE-SC-4
A14: ='Результаты аудита'!E14 -> T-CODE-IMG | B14: T-CODE-IMG-0 | C14: T-CODE-IMG-1 | D14: T-CODE-IMG-2 | E14: T-CODE-IMG-3 | F14: T-CODE-IMG-4
A15: ='Результаты аудита'!E15 -> T-CODE-SECDN | B15: T-CODE-SECDN-0 | C15: T-CODE-SECDN-1 | D15: T-CODE-SECDN-2 | E15: T-CODE-SECDN-3 | G15: T-CODE-SECDN-4
A16: ='Результаты аудита'!E16 -> T-CODE-DOCKERFS | B16: T-CODE-DOCKERFS-0 | C16: T-CODE-DOCKERFS-1 | D16: T-CODE-DOCKERFS-2
A17: ='Результаты аудита'!E17 -> T-PREPROD-DAST | B17: T-PREPROD-DAST-0 | E17: T-PREPROD-DAST-1 | F17: T-PREPROD-DAST-2 | G17: T-PREPROD-DAST-3 | H17: T-PREPROD-DAST-4
A18: ='Результаты аудита'!E18 -> T-PREPROD-PENTEST | B18: T-PREPROD-PENTEST-0 | C18: T-PREPROD-PENTEST-1 | D18: T-PREPROD-PENTEST-2 | H18: T-PREPROD-PENTEST-4
A19: ='Результаты аудита'!E21 -> T-PREPROD-VULN | B19: T-PREPROD-VULN-0 | D19: T-PREPROD-VULN-1 | F19: T-PREPROD-VULN-2 | G19: T-PREPROD-VULN-3 | I19: T-PREPROD-VULN-4
A20: ='Результаты аудита'!E19 -> T-PREPROD-SECTEST | B20: T-PREPROD-SECTEST-0 | C20: T-PREPROD-SECTEST-1 | D20: T-PREPROD-SECTEST-2 | H20: T-PREPROD-SECTEST-3
A21: ='Результаты аудита'!E20 -> T-PREPROD-MANSEC | B21: T-PREPROD-MANSEC-0 | D21: T-PREPROD-MANSEC-1 | E21: T-PREPROD-MANSEC-2
A22: ='Результаты аудита'!E22 -> T-PROD-SM | B22: T-PROD-SM-0 | C22: T-PROD-SM-1 | D22: T-PROD-SM-2 | E22: T-PROD-SM-3 | G22: T-PROD-SM-4
A23: ='Результаты аудита'!E23 -> T-PROD-DAST | B23: T-PROD-DAST-0 | F23: T-PROD-DAST-1 | G23: T-PROD-DAST-2 | H23: T-PROD-DAST-3 | I23: T-PROD-DAST-4
A24: ='Результаты аудита'!E24 -> T-PROD-PENTEST | B24: T-PROD-PENTEST-0 | D24: T-PROD-PENTEST-1 | E24: T-PROD-PENTEST-2 | F24: T-PROD-PENTEST-3 | I24: T-PROD-PENTEST-4
A25: ='Результаты аудита'!E25 -> T-PROD-ACCESS | B25: T-PROD-ACCESS-0 | C25: T-PROD-ACCESS-1 | E25: T-PROD-ACCESS-2 | F25: T-PROD-ACCESS-3 | I25: T-PROD-ACCESS-4
A26: ='Результаты аудита'!E26 -> T-PROD-NETWORK | B26: T-PROD-NETWORK-0 | C26: T-PROD-NETWORK-1 | D26: T-PROD-NETWORK-2 | E26: T-PROD-NETWORK-3
A27: ='Результаты аудита'!E27 -> T-PROD-RUN | B27: T-PROD-RUN-0 | D27: T-PROD-RUN-1 | E27: T-PROD-RUN-2 | G27: T-PROD-RUN-3
A28: ='Результаты аудита'!E28 -> T-PROD-VULN | B28: T-PROD-VULN-0 | C28: T-PROD-VULN-1 | D28: T-PROD-VULN-2 | E28: T-PROD-VULN-3 | G28: T-PROD-VULN-4
A29: ='Результаты аудита'!E29 -> T-PROD-EVENTS | B29: T-PROD-EVENTS-0 | D29: T-PROD-EVENTS-2 | E29: T-PROD-EVENTS-3
A30: ='Результаты аудита'!E30 -> P-EDU-AWR | B30: P-EDU-AWR-0 | C30: P-EDU-AWR-1 | E30: P-EDU-AWR-2 | G30: P-EDU-AWR-3 | H30: P-EDU-AWR-4
A31: ='Результаты аудита'!E31 -> P-EDU-KB | B31: P-EDU-KB-0 | C31: P-EDU-KB-1 | E31: P-EDU-KB-2 | F31: P-EDU-KB-3 | G31: P-EDU-KB-4
A32: ='Результаты аудита'!E32 -> P-REQ-TM | B32: P-REQ-TM-0 | D32: P-REQ-TM-1 | E32: P-REQ-TM-2 | F32: P-REQ-TM-3 | G32: P-REQ-TM-4
A33: ='Результаты аудита'!E33 -> P-REQ-RD | B33: P-REQ-RD-0 | C33: P-REQ-RD-1 | D33: P-REQ-RD-2 | F33: P-REQ-RD-3 | H33: P-REQ-RD-4
A34: ='Результаты аудита'!E34 -> P-REQ-CR | B34: P-REQ-CR-0 | C34: P-REQ-CR-1 | D34: P-REQ-CR-2 | G34: P-REQ-CR-3 | H34: P-REQ-CR-4
A35: ='Результаты аудита'!E35 -> P-REQ-STDR-App | B35: P-REQ-STDR-App-0 | E35: P-REQ-STDR-App-1 | F35: P-REQ-STDR-App-2 | G35: P-REQ-STDR-App-3 | H35: P-REQ-STDR-App-4
A36: ='Результаты аудита'!E36 -> P-REQ-STDR-Infr | B36: P-REQ-STDR-Infr-0 | C36: P-REQ-STDR-Infr-1 | D36: P-REQ-STDR-Infr-2 | E36: P-REQ-STDR-Infr-3 | G36: P-REQ-STDR-Infr-4
A37: ='Результаты аудита'!E37 -> P-DEFECT-MNG | B37: P-DEFECT-MNG-0 | C37: P-DEFECT-MNG-1 | D37: P-DEFECT-MNG-2 | E37: P-DEFECT-MNG-3 | I37: P-DEFECT-MNG-4
A38: ='Результаты аудита'!E38 -> P-DEFECT-CNS | B38: P-DEFECT-CNS-0 | E38: P-DEFECT-CNS-1 | F38: P-DEFECT-CNS-2 | G38: P-DEFECT-CNS-3 | H38: P-DEFECT-CNS-4
A39: ='Результаты аудита'!E39 -> P-MET-SET | B39: P-MET-SET-0 | E39: P-MET-SET-2 | F39: P-MET-SET-3
A40: ='Результаты аудита'!E40 -> P-MET-EX | B40: P-MET-EX-0 | E40: P-MET-EX-2 | F40: P-MET-EX-3 | H40: P-MET-EX-4
...

Sheet miniRoadmap
A1: Модель | B1: Домены и поддомены | C1: 202х | G1: 202х+1 | K1: 202х+2
C2: Q1 | D2: Q2 | E2: Q3 | F2: Q4 | G2: Q1 | H2: Q2 | I2: Q3 | J2: Q4 | K2: Q1 | L2: Q2 | M2: Q3 | N2: Q4
A3: Технологии | B3: ='Результаты аудита'!D3 -> Контроль использования сторонних компонентов | E3: Внедрение решения OSA\SCA
B4: ='Результаты аудита'!D4 -> Управление артефактами
B5: ='Результаты аудита'!D5 -> Защита рабочих мест разработчика | I5: Внедрение и настройка решения класса XDR
B6: ='Результаты аудита'!D6 -> Защита секретов | G6: Внедрение средство управления секретами (HashiCorp Vault )
B7: ='Результаты аудита'!D7 -> Защита Build-среды | C7: Харденинг узлов сборки , настройка мониторинга, сетевых доступов к workers и пр.
B8: ='Результаты аудита'!D8 -> Защита source code management (SCM) | C8: Харденинг SCM
B9: ='Результаты аудита'!D9 -> Контроль внесения изменений в исходный код | C9: Харденинг SCM, настройка RBAC
B10: ='Результаты аудита'!D10 -> Защита конвейера сборки | C10: Харденинг СI\CD, настройка RBAC, настройка и анализ логов pipeline и пр.
B11: ='Результаты аудита'!D11 -> Безопасность заказной разработки | E11: Формирование Регламента приемки заказной разработки и настройка инструментов анализа SBOM
B12: ='Результаты аудита'!D12 -> Статический анализ (SAST) | E12: Внедрение решения SAST
B13: ='Результаты аудита'!D13 -> Композиционный анализ (SCA) | E13: Внедрение решения OSA\SCA
B14: ='Результаты аудита'!D14 -> Анализ образов контейнеров | D14: Внедрить анализ образов контейнеров и защиту runtime для всех команд , настроить контроль конфигураций
B15: ='Результаты аудита'!D15 -> Идентификация секретов | E15: Внедрить решение Secret detection
B16: ='Результаты аудита'!D16 -> Контроль безопасности Dockerfile’ов | D16: Внедрить инструмент анализа dockerfile'ов
B17: ='Результаты аудита'!D17 -> Динамический анализ приложений (DAST) в PREPROD среде | G17: Внедрить решение класса DAST
B18: ='Результаты аудита'!D18 -> Тестирование на проникновение перед внедрением приложений в продуктив | G18: Формализация и проведение тестирований на проникновение при приемочных испытаниях ПО
B19: ='Результаты аудита'!D19 -> Функциональное ИБ-тестирование | E19: Внедрить практики автотестов, выполняющих проверки по ИБ
B20: ='Результаты аудита'!D20 -> Контроль безопасности манифестов (k8s, terraform и т.д.) | D20: Внедрить анализ образов контейнеров и защиту runtime для всех команд
B21: ='Результаты аудита'!D21 -> Анализ инфраструктуры PREPROD среды на уязвимости
B22: ='Результаты аудита'!D22 -> Управление секретами | G22: Внедрить средство управления секретами (Hashicorp vault)
B23: ='Результаты аудита'!D23 -> Динамический анализ приложений (DAST) в продуктивной среде
B24: ='Результаты аудита'!D24 -> Тестирование на проникновение продуктивной среды | C24: Выполнить сегментацию сети, настроить минимальные сетевые доступы к k8s
B25: ='Результаты аудита'!D25 -> Управление изменениями инфраструктуры и доступом к ней | C25: Выполнить сегментацию сети, настроить минимальные сетевые доступы к k8s | E25: Внедрение решения Container security. | J25: Настройка admission policy
B26: ='Результаты аудита'!D26 -> Контроль сетевого трафика (L4-L7) | E26: Внедрение решения Container security. | J26: Настройка admission policy
B27: ='Результаты аудита'!D27 -> Контроль выполняемых и процессов и их прав доступа | E27: Внедрение решения Container security.
B28: ='Результаты аудита'!D28 -> Анализ инфраструктуры PROD среды на уязвимости
B29: ='Результаты аудита'!D29 -> Анализ событий информационной безопасности | F29: После внедрения решения Container Security создать правила корреляции от него в SIEM
A30: Процессы | B30: ='Результаты аудита'!D30 -> Обучение специалистов | E30: Разработать план обучения специалистов, соглсасование плана обучений
B31: ='Результаты аудита'!D31 -> Управление базой знаний DSO | E31: Назначение ответственных за БЗ и регламентация процессов управления БЗ
B32: ='Результаты аудита'!D32 -> Оценка критичности приложений и моделирование угроз | I32: Разработать методику моделирования угроз ИБ
B33: ='Результаты аудита'!D33 -> Определение требований ИБ, предъявляемых к ПО | F33: 1.Разработать положение по безопасной разработке ПО 2.Разработать регламент безопасной разработки ПО
B34: ='Результаты аудита'!D34 -> Контроль выполнения требований ИБ
B35: ='Результаты аудита'!D35 -> Разработка стандартов конфигураций разрабатываемого ПО | I35: Разработка стандарта
B36: ='Результаты аудита'!D36 -> Разработка стандартов конфигураций для компонентов инфраструктуры | H36: Разработка стандарта
B37: ='Результаты аудита'!D37 -> Обработка дефектов ИБ | D37: Разработать регламент управления уязвимостями
B38: ='Результаты аудита'!D38 -> Консолидация дефектов ИБ | D38: Разработать регламент управления уязвимостями | G38: Внедрить ресурс хранения отчетов тестирований безопасности
B39: ='Результаты аудита'!D39 -> Управление набором метрик ИБ
B40: ='Результаты аудита'!D40 -> Контроль исполнения метрик
...

Sheet Документы для процессов DSO
A1: Предполагаемый базовый перечень и состав документов
A2: Название документа | B2: Предполагаемое содержания (разделы) документа | C2: Примечание
A3: Отчет по результатам проведения оценки зрелости процессов безопасной разработки по фреймворку DAF
B4: Описание текущих процессов разработки ПО;
B5: Перечень сильных/слабых сторон и возможностей для улучшения/развития;
B6: Рекомендации по встраиванию практик безопасной разработки на каждом из этапов разработки ПО.
A7: Проект документа «Положение по безопасной разработке программного обеспечения»
B8: 1 Общие положения
B9: 1.1 Назначение и область действия документа
B10: 1.2 Нормативные документы, на основе которых составлен настоящий документ
B11: 2 Описание процессов безопасной разработки ПО
B12: 2.1 Основные принципы безопасной разработки ПО
B13: 2.2 Описание жизненного цикла безопасной разработки ПО
B14: 2.3 Функциональные роли участников безопасной разработки ПО
B15: 3 Требования ИБ на различных этапах жизненного цикла разработки ПО
B16: 3.1 Общие требования ИБ
B17: 3.2 Требования к этапу планирования функционала ПО
B18: 3.3 Требования к этапу проектирования ПО
B19: 3.4 Требования к этапу разработки ПО
... B25: 4 Контроль и ответственность за выполнение требований настоящего документа
A26: Проект документа «Регламент процесса безопасной разработки ПО»
B27: 1 Общие положения
B28: 1.1 Назначение и область действия документа
B29: 1.2 Нормативные документы, на основе которых составлен настоящий документ
B30: 2 Функциональные роли процесса безопасной разработки ПО
B31: 2.1 Перечень функциональных ролей, участвующих в безопасной разработки ПО
B32: 2.2 Описание и задачи функциональных ролей, участвующих в безопасной разработки ПО
B33: 3 Жизненный цикл безопасной разработки ПО
B34: 3.1 Полный жизненный цикл безопасной разработки ПО
B35: 3.2 Изменение/доработка ПО с точки зрения информационной безопасности
B36: 4 Процессы безопасной разработки ПО
B37: 4.1 Обучение работников в части безопасной разработки ПО
B38: 4.2 Анализ применимости базовых требований ИБ к ПО
... B54: 4.18 Процесс обеспечения безопасности ПО на этапе вывода из эксплуатации
A55: Проект документа «Регламент управления дефектами, идентифицированными в процессе разработки ПО»
B56: 1 Общие положения
B57: 1.1 Назначение и область действия документа
B58: 1.2 Нормативные документы, на основе которых составлен настоящий документ
B59: 2 Общие положения
B60: 2.1 Сроки и правила устранения выявленных уязвимостей в разрабатываемом ПО
...

Sheet FTE AppSec
B1: Язык разработки | C1: Коэффициент сложности | D1: Используемый фреймворк | E1: Коэф. сложности для фреймворка | F1: Тип приложения | G1: Коэффициент сложности приложения | H1: Количество строк кода ВСЕГО (в тысячах) | I1: СРЕДНЕЕ количество ИЗМЕНЯЕМЫХ каждый релиз строк код (в тысячах) | J1: Частота релизов (кол-во раз в год) | K1: Это приложение сканирует SAST? | L1: Это приложение сканирует DAST? | M1: Это приложение сканирует OSA\SCA? | N1: Образы контейнеров этого приложения анализируются? | O1: РЕЗУЛЬТАТ: Затрачиваемое время на анализ результатов AppSec'ом, часов в год | V1: Да
A2: Приложение 1 | B2: TypeScript | C2: =IFERROR(VLOOKUP(B2,Таблица1[#All],2,FALSE),"-") -> 1.1 | F2: веб-приложение | G2: =VLOOKUP(F2,Таблица3[#All],2,FALSE) -> 1 | H2: 300 | I2: 1 | J2: 24 | K2: Да | L2: Да | M2: Да | N2: Да | O2: =$R$8*I2*(IF(K2="Да",1,0)*$R$9+IF(L2="Да",1,0)*$R$10+IF(M2="Да",1,0)*$R$11+IF(N2="Да",1,0)*$R$12)*J2*IF($R$3="Да",0.5,1)+$R$8*H2*(IF(K2="Да",1,0)*$R$9+IF(L2="Да",1,0)*$R$10+IF(M2="Да",1,0)*$R$11+IF(N2="Да",1,0)*$R$12)*IF($R$3="Да",0.5,1) -> 206.145 | Q2: Итого сколько нужно AppSec'ов (FTE) | R2: Есть и используется ли в компании ASOC? | V2: Нет
A3: Приложение 2 | B3: C# | C3: =IFERROR(VLOOKUP(B3,Таблица1[#All],2,FALSE),"-") -> 1.6 | F3: мобильное приложение | G3: =VLOOKUP(F3,Таблица3[#All],2,FALSE) -> 1.6 | H3: 200 | I3: 1 | J3: 20 | K3: Да | L3: Да | M3: Да | N3: Да | O3: =$R$8*I3*(IF(K3="Да",1,0)*$R$9+IF(L3="Да",1,0)*$R$10+IF(M3="Да",1,0)*$R$11+IF(N3="Да",1,0)*$R$12)*J3*IF($R$3="Да",0.5,1)+$R$8*H3*(IF(K3="Да",1,0)*$R$9+IF(L3="Да",1,0)*$R$10+IF(M3="Да",1,0)*$R$11+IF(N3="Да",1,0)*$R$12)*IF($R$3="Да",0.5,1) -> 139.975 | Q3: =(SUM(O2:O301)+R13+R6+R7)*V5/V4 -> 1.7484659 | R3: Да
A4: Приложение 3 | B4: Kotlin | C4: =IFERROR(VLOOKUP(B4,Таблица1[#All],2,FALSE),"-") -> 1.1 | F4: веб-приложение | G4: =IFERROR(VLOOKUP(F4,Таблица3[#All],2,FALSE),"-") -> 1 | H4: 250 | I4: 1 | J4: 12 | K4: Да | L4: Да | M4: Да | N4: Да | O4: =$R$8*I4*(IF(K4="Да",1,0)*$R$9+IF(L4="Да",1,0)*$R$10+IF(M4="Да",1,0)*$R$11+IF(N4="Да",1,0)*$R$12)*J4*IF($R$3="Да",0.5,1)+$R$8*H4*(IF(K4="Да",1,0)*$R$9+IF(L4="Да",1,0)*$R$10+IF(M4="Да",1,0)*$R$11+IF(N4="Да",1,0)*$R$12)*IF($R$3="Да",0.5,1) -> 166.6975 | U4: Количество рабочих часов в году | V4: =8*247 -> 1976
A5: Приложение 4 | B5: Python | C5: =IFERROR(VLOOKUP(B5,Таблица1[#All],2,FALSE),"-") -> 1 | F5: веб-приложение | G5: =IFERROR(VLOOKUP(F5,Таблица3[#All],2,FALSE),"-") -> 1 | H5: 400 | I5: 2 | J5: 24 | K5: Да | L5: Да | M5: Да | N5: Да | O5: =$R$8*I5*(IF(K5="Да",1,0)*$R$9+IF(L5="Да",1,0)*$R$10+IF(M5="Да",1,0)*$R$11+IF(N5="Да",1,0)*$R$12)*J5*IF($R$3="Да",0.5,1)+$R$8*H5*(IF(K5="Да",1,0)*$R$9+IF(L5="Да",1,0)*$R$10+IF(M5="Да",1,0)*$R$11+IF(N5="Да",1,0)*$R$12)*IF($R$3="Да",0.5,1) -> 285.04 | Q5: Ограничения | U5: Коэффициент расчета FTE (отпуски, болезни и прочее) | V5: 1.1
A6: Приложение 5 | B6: Solidity | C6: =IFERROR(VLOOKUP(B6,Таблица1[#All],2,FALSE),"-") -> 1.1 | F6: веб-приложение | G6: =IFERROR(VLOOKUP(F6,Таблица3[#All],2,FALSE),"-") -> 1 | H6: 400 | I6: 1 | J6: 12 | K6: Да | L6: Да | M6: Да | N6: Да | O6: =$R$8*I6*(IF(K6="Да",1,0)*$R$9+IF(L6="Да",1,0)*$R$10+IF(M6="Да",1,0)*$R$11+IF(N6="Да",1,0)*$R$12)*J6*IF($R$3="Да",0.5,1)+$R$8*H6*(IF(K6="Да",1,0)*$R$9+IF(L6="Да",1,0)*$R$10+IF(M6="Да",1,0)*$R$11+IF(N6="Да",1,0)*$R$12)*IF($R$3="Да",0.5,1) -> 262.135 | Q6: Постановка и контроль задач на устранения найденных в приложениях уязвимостях силами AppSec-инеженера, часов | R6: =SUM(I2:I301)*SUM(J2:J301)*0.001*12 -> 37.488
A7: Приложение 6 | B7: Kotlin | C7: =IFERROR(VLOOKUP(B7,Таблица1[#All],2,FALSE),"-") -> 1.1 | F7: мобильное приложение | G7: =IFERROR(VLOOKUP(F7,Таблица3[#All],2,FALSE),"-") -> 1.6 | H7: 200 | I7: 1 | J7: 36 | K7: Да | L7: Да | M7: Да | N7: Да | O7: =$R$8*I7*(IF(K7="Да",1,0)*$R$9+IF(L7="Да",1,0)*$R$10+IF(M7="Да",1,0)*$R$11+IF(N7="Да",1,0)*$R$12)*J7*IF($R$3="Да",0.5,1)+$R$8*H7*(IF(K7="Да",1,0)*$R$9+IF(L7="Да",1,0)*$R$10+IF(M7="Да",1,0)*$R$11+IF(N7="Да",1,0)*$R$12)*IF($R$3="Да",0.5,1) -> 150.155 | Q7: Консультации команд разработки силами AppSec-инженера по верифицированным уязвимостям, часов | R7: =COUNTA(B2:B301)*12 -> 144
A8: Приложение 7 | B8: Perl | C8: =IFERROR(VLOOKUP(B8,Таблица1[#All],2,FALSE),"-") -> 1.1 | F8: веб-приложение | G8: =IFERROR(VLOOKUP(F8,Таблица3[#All],2,FALSE),"-") -> 1 | H8: 100 | I8: 0.5 | J8: 12 | K8: Да | L8: Да | M8: Да | N8: Да | O8: =$R$8*I8*(IF(K8="Да",1,0)*$R$9+IF(L8="Да",1,0)*$R$10+IF(M8="Да",1,0)*$R$11+IF(N8="Да",1,0)*$R$12)*J8*IF($R$3="Да",0.5,1)+$R$8*H8*(IF(K8="Да",1,0)*$R$9+IF(L8="Да",1,0)*$R$10+IF(M8="Да",1,0)*$R$11+IF(N8="Да",1,0)*$R$12)*IF($R$3="Да",0.5,1) -> 67.4425 | Q8: СРЕДНЕЕ время обработки 1-го найденного дефекта\уязвимости, часов | R8: 0.05
A9: Приложение 8 | B9: Java | C9: =IFERROR(VLOOKUP(B9,Таблица1[#All],2,FALSE),"-") -> 1.1 | F9: веб-приложение | G9: =IFERROR(VLOOKUP(F9,Таблица3[#All],2,FALSE),"-") -> 1 | H9: 800 | I9: 1 | J9: 24 | K9: Да | L9: Да | M9: Да | N9: Да | O9: =$R$8*I9*(IF(K9="Да",1,0)*$R$9+IF(L9="Да",1,0)*$R$10+IF(M9="Да",1,0)*$R$11+IF(N9="Да",1,0)*$R$12)*J9*IF($R$3="Да",0.5,1)+$R$8*H9*(IF(K9="Да",1,0)*$R$9+IF(L9="Да",1,0)*$R$10+IF(M9="Да",1,0)*$R$11+IF(N9="Да",1,0)*$R$12)*IF($R$3="Да",0.5,1) -> 524.27 | Q9: SAST. СРЕДНЕЕ количество дефектов на 1000 строк кода | R9: 5
A10: Приложение 9 | B10: JavaScript | C10: =IFERROR(VLOOKUP(B10,Таблица1[#All],2,FALSE),"-") -> 1.1 | F10: веб-приложение | G10: =IFERROR(VLOOKUP(F10,Таблица3[#All],2,FALSE),"-") -> 1 | H10: 300 | I10: 1 | J10: 36 | K10: Да | L10: Да | M10: Да | N10: Да | O10: =$R$8*I10*(IF(K10="Да",1,0)*$R$9+IF(L10="Да",1,0)*$R$10+IF(M10="Да",1,0)*$R$11+IF(N10="Да",1,0)*$R$12)*J10*IF($R$3="Да",0.5,1)+$R$8*H10*(IF(K10="Да",1,0)*$R$9+IF(L10="Да",1,0)*$R$10+IF(M10="Да",1,0)*$R$11+IF(N10="Да",1,0)*$R$12)*IF($R$3="Да",0.5,1) -> 213.78 | Q10: DAST. СРЕДНЕЕ количество дефектов на 1000 строк кода | R10: 0.25
A11: Приложение 10 | B11: PHP | C11: =IFERROR(VLOOKUP(B11,Таблица1[#All],2,FALSE),"-") -> 1 | F11: веб-приложение | G11: =IFERROR(VLOOKUP(F11,Таблица3[#All],2,FALSE),"-") -> 1 | H11: 400 | I11: 1 | J11: 36 | K11: Да | L11: Да | M11: Да | N11: Да | O11: =$R$8*I11*(IF(K11="Да",1,0)*$R$9+IF(L11="Да",1,0)*$R$10+IF(M11="Да",1,0)*$R$11+IF(N11="Да",1,0)*$R$12)*J11*IF($R$3="Да",0.5,1)+$R$8*H11*(IF(K11="Да",1,0)*$R$9+IF(L11="Да",1,0)*$R$10+IF(M11="Да",1,0)*$R$11+IF(N11="Да",1,0)*$R$12)*IF($R$3="Да",0.5,1) -> 277.405 | Q11: SCA. СРЕДНЕЕ количество open source проектов, используемых в разработке | R11: 20
A12: Приложение 11 | B12: Python | C12: =IFERROR(VLOOKUP(B12,Таблица1[#All],2,FALSE),"-") -> 1 | F12: веб-приложение | G12: =IFERROR(VLOOKUP(F12,Таблица3[#All],2,FALSE),"-") -> 1 | H12: 52 | I12: 0.25 | J12: 36 | K12: Да | L12: Да | M12: Да | N12: Да | O12: =$R$8*I12*(IF(K12="Да",1,0)*$R$9+IF(L12="Да",1,0)*$R$10+IF(M12="Да",1,0)*$R$11+IF(N12="Да",1,0)*$R$12)*J12*IF($R$3="Да",0.5,1)+$R$8*H12*(IF(K12="Да",1,0)*$R$9+IF(L12="Да",1,0)*$R$10+IF(M12="Да",1,0)*$R$11+IF(N12="Да",1,0)*$R$12)*IF($R$3="Да",0.5,1) -> 38.81125 | Q12: Container Analisys. СРЕДНЕЕ количество дефектов на 1 анализируемый образ | R12: 0.2
A13: Приложение 12 | B13: Python | C13: =IFERROR(VLOOKUP(B13,Таблица1[#All],2,FALSE),"-") -> 1 | F13: веб-приложение | G13: =IFERROR(VLOOKUP(F13,Таблица3[#All],2,FALSE),"-") -> 1 | H13: 78 | I13: 0.25 | J13: 12 | K13: Да | L13: Да | M13: Да | N13: Да | O13: =$R$8*I13*(IF(K13="Да",1,0)*$R$9+IF(L13="Да",1,0)*$R$10+IF(M13="Да",1,0)*$R$11+IF(N13="Да",1,0)*$R$12)*J13*IF($R$3="Да",0.5,1)+$R$8*H13*(IF(K13="Да",1,0)*$R$9+IF(L13="Да",1,0)*$R$10+IF(M13="Да",1,0)*$R$11+IF(N13="Да",1,0)*$R$12)*IF($R$3="Да",0.5,1) -> 51.53625 | Q13: Разработка ЕЖЕМЕСЯЧНЫХ отчетов по анализу ВСЕХ приложений (часов в год) | R13: =COUNTA(B2:B301)*4*12 -> 576
A14: Приложение 13 | C14: =IFERROR(VLOOKUP(B14,Таблица1[#All],2,FALSE),"-") -> - | G14: =IFERROR(VLOOKUP(F14,Таблица3[#All],2,FALSE),"-") -> - | H14: 0 | J14: 0 | K14: Нет | L14: Нет | M14: Нет | N14: Нет | O14: =$R$8*I14*(IF(K14="Да",1,0)*$R$9+IF(L14="Да",1,0)*$R$10+IF(M14="Да",1,0)*$R$11+IF(N14="Да",1,0)*$R$12)*J14*IF($R$3="Да",0.5,1)+$R$8*H14*(IF(K14="Да",1,0)*$R$9+IF(L14="Да",1,0)*$R$10+IF(M14="Да",1,0)*$R$11+IF(N14="Да",1,0)*$R$12)*IF($R$3="Да",0.5,1) -> 0
A15: Приложение 14 | C15: =IFERROR(VLOOKUP(B15,Таблица1[#All],2,FALSE),"-") -> - | G15: =IFERROR(VLOOKUP(F15,Таблица3[#All],2,FALSE),"-") -> - | H15: 0 | J15: 0 | K15: Нет | L15: Нет | M15: Нет | N15: Нет | O15: =$R$8*I15*(IF(K15="Да",1,0)*$R$9+IF(L15="Да",1,0)*$R$10+IF(M15="Да",1,0)*$R$11+IF(N15="Да",1,0)*$R$12)*J15*IF($R$3="Да",0.5,1)+$R$8*H15*(IF(K15="Да",1,0)*$R$9+IF(L15="Да",1,0)*$R$10+IF(M15="Да",1,0)*$R$11+IF(N15="Да",1,0)*$R$12)*IF($R$3="Да",0.5,1) -> 0 | Q15: Тип приложения | R15: Сложность динамического анализа (от 1 до 2)
A16: Приложение 15 | C16: =IFERROR(VLOOKUP(B16,Таблица1[#All],2,FALSE),"-") -> - | G16: =IFERROR(VLOOKUP(F16,Таблица3[#All],2,FALSE),"-") -> - | H16: 0 | J16: 0 | K16: Нет | L16: Нет | M16: Нет | N16: Нет | O16: =$R$8*I16*(IF(K16="Да",1,0)*$R$9+IF(L16="Да",1,0)*$R$10+IF(M16="Да",1,0)*$R$11+IF(N16="Да",1,0)*$R$12)*J16*IF($R$3="Да",0.5,1)+$R$8*H16*(IF(K16="Да",1,0)*$R$9+IF(L16="Да",1,0)*$R$10+IF(M16="Да",1,0)*$R$11+IF(N16="Да",1,0)*$R$12)*IF($R$3="Да",0.5,1) -> 0 | Q16: веб-приложение | R16: 1
A17: Приложение 16 | C17: =IFERROR(VLOOKUP(B17,Таблица1[#All],2,FALSE),"-") -> - | G17: =IFERROR(VLOOKUP(F17,Таблица3[#All],2,FALSE),"-") -> - | H17: 0 | J17: 0 | K17: Нет | L17: Нет | M17: Нет | N17: Нет | O17: =$R$8*I17*(IF(K17="Да",1,0)*$R$9+IF(L17="Да",1,0)*$R$10+IF(M17="Да",1,0)*$R$11+IF(N17="Да",1,0)*$R$12)*J17*IF($R$3="Да",0.5,1)+$R$8*H17*(IF(K17="Да",1,0)*$R$9+IF(L17="Да",1,0)*$R$10+IF(M17="Да",1,0)*$R$11+IF(N17="Да",1,0)*$R$12)*IF($R$3="Да",0.5,1) -> 0 | Q17: мобильное приложение | R17: 1.6
A18: Приложение 17 | C18: =IFERROR(VLOOKUP(B18,Таблица1[#All],2,FALSE),"-") -> - | G18: =IFERROR(VLOOKUP(F18,Таблица3[#All],2,FALSE),"-") -> - | H18: 0 | J18: 0 | K18: Нет | L18: Нет | M18: Нет | N18: Нет | O18: =$R$8*I18*(IF(K18="Да",1,0)*$R$9+IF(L18="Да",1,0)*$R$10+IF(M18="Да",1,0)*$R$11+IF(N18="Да",1,0)*$R$12)*J18*IF($R$3="Да",0.5,1)+$R$8*H18*(IF(K18="Да",1,0)*$R$9+IF(L18="Да",1,0)*$R$10+IF(M18="Да",1,0)*$R$11+IF(N18="Да",1,0)*$R$12)*IF($R$3="Да",0.5,1) -> 0 | Q18: толстое приложение | R18: 1.9
A19: Приложение 18 | C19: =IFERROR(VLOOKUP(B19,Таблица1[#All],2,FALSE),"-") -> - | G19: =IFERROR(VLOOKUP(F19,Таблица3[#All],2,FALSE),"-") -> - | H19: 0 | J19: 0 | K19: Нет | L19: Нет | M19: Нет | N19: Нет | O19: =$R$8*I19*(IF(K19="Да",1,0)*$R$9+IF(L19="Да",1,0)*$R$10+IF(M19="Да",1,0)*$R$11+IF(N19="Да",1,0)*$R$12)*J19*IF($R$3="Да",0.5,1)+$R$8*H19*(IF(K19="Да",1,0)*$R$9+IF(L19="Да",1,0)*$R$10+IF(M19="Да",1,0)*$R$11+IF(N19="Да",1,0)*$R$12)*IF($R$3="Да",0.5,1) -> 0
A20: Приложение 19 | C20: =IFERROR(VLOOKUP(B20,Таблица1[#All],2,FALSE),"-") -> - | G20: =IFERROR(VLOOKUP(F20,Таблица3[#All],2,FALSE),"-") -> - | H20: 0 | J20: 0 | K20: Нет | L20: Нет | M20: Нет | N20: Нет | O20: =$R$8*I20*(IF(K20="Да",1,0)*$R$9+IF(L20="Да",1,0)*$R$10+IF(M20="Да",1,0)*$R$11+IF(N20="Да",1,0)*$R$12)*J20*IF($R$3="Да",0.5,1)+$R$8*H20*(IF(K20="Да",1,0)*$R$9+IF(L20="Да",1,0)*$R$10+IF(M20="Да",1,0)*$R$11+IF(N20="Да",1,0)*$R$12)*IF($R$3="Да",0.5,1) -> 0
A21: Приложение 20 | C21: =IFERROR(VLOOKUP(B21,Таблица1[#All],2,FALSE),"-") -> - | G21: =IFERROR(VLOOKUP(F21,Таблица3[#All],2,FALSE),"-") -> - | H21: 0 | J21: 0 | K21: Нет | L21: Нет | M21: Нет | N21: Нет | O21: =$R$8*I21*(IF(K21="Да",1,0)*$R$9+IF(L21="Да",1,0)*$R$10+IF(M21="Да",1,0)*$R$11+IF(N21="Да",1,0)*$R$12)*J21*IF($R$3="Да",0.5,1)+$R$8*H21*(IF(K21="Да",1,0)*$R$9+IF(L21="Да",1,0)*$R$10+IF(M21="Да",1,0)*$R$11+IF(N21="Да",1,0)*$R$12)*IF($R$3="Да",0.5,1) -> 0 | Q21: ЯП | R21: коэф. Сложности (от 1 до 2) | S21: Группы знаний | T21: Примечание
A22: Приложение 21 | C22: =IFERROR(VLOOKUP(B22,Таблица1[#All],2,FALSE),"-") -> - | G22: =IFERROR(VLOOKUP(F22,Таблица3[#All],2,FALSE),"-") -> - | H22: 0 | J22: 0 | K22: Нет | L22: Нет | M22: Нет | N22: Нет | O22: =$R$8*I22*(IF(K22="Да",1,0)*$R$9+IF(L22="Да",1,0)*$R$10+IF(M22="Да",1,0)*$R$11+IF(N22="Да",1,0)*$R$12)*J22*IF($R$3="Да",0.5,1)+$R$8*H22*(IF(K22="Да",1,0)*$R$9+IF(L22="Да",1,0)*$R$10+IF(M22="Да",1,0)*$R$11+IF(N22="Да",1,0)*$R$12)*IF($R$3="Да",0.5,1) -> 0 | Q22: ABAP | R22: 2 | S22: 5 | T22: 5 - мутные языки
A23: Приложение 22 | C23: =IFERROR(VLOOKUP(B23,Таблица1[#All],2,FALSE),"-") -> - | G23: =IFERROR(VLOOKUP(F23,Таблица3[#All],2,FALSE),"-") -> - | H23: 0 | J23: 0 | K23: Нет | L23: Нет | M23: Нет | N23: Нет | O23: =$R$8*I23*(IF(K23="Да",1,0)*$R$9+IF(L23="Да",1,0)*$R$10+IF(M23="Да",1,0)*$R$11+IF(N23="Да",1,0)*$R$12)*J23*IF($R$3="Да",0.5,1)+$R$8*H23*(IF(K23="Да",1,0)*$R$9+IF(L23="Да",1,0)*$R$10+IF(M23="Да",1,0)*$R$11+IF(N23="Да",1,0)*$R$12)*IF($R$3="Да",0.5,1) -> 0 | Q23: Apex | R23: 1.5 | S23: 5 | T23: 5 - мутные языки
A24: Приложение 23 | C24: =IFERROR(VLOOKUP(B24,Таблица1[#All],2,FALSE),"-") -> - | G24: =IFERROR(VLOOKUP(F24,Таблица3[#All],2,FALSE),"-") -> - | H24: 0 | J24: 0 | K24: Нет | L24: Нет | M24: Нет | N24: Нет | O24: =$R$8*I24*(IF(K24="Да",1,0)*$R$9+IF(L24="Да",1,0)*$R$10+IF(M24="Да",1,0)*$R$11+IF(N24="Да",1,0)*$R$12)*J24*IF($R$3="Да",0.5,1)+$R$8*H24*(IF(K24="Да",1,0)*$R$9+IF(L24="Да",1,0)*$R$10+IF(M24="Да",1,0)*$R$11+IF(N24="Да",1,0)*$R$12)*IF($R$3="Да",0.5,1) -> 0 | Q24: C# | R24: 1.6 | S24: 2 | T24: 2 - бэкенд
A25: Приложение 24 | C25: =IFERROR(VLOOKUP(B25,Таблица1[#All],2,FALSE),"-") -> - | G25: =IFERROR(VLOOKUP(F25,Таблица3[#All],2,FALSE),"-") -> - | H25: 0 | J25: 0 | K25: Нет | L25: Нет | M25: Нет | N25: Нет | O25: =$R$8*I25*(IF(K25="Да",1,0)*$R$9+IF(L25="Да",1,0)*$R$10+IF(M25="Да",1,0)*$R$11+IF(N25="Да",1,0)*$R$12)*J25*IF($R$3="Да",0.5,1)+$R$8*H25*(IF(K25="Да",1,0)*$R$9+IF(L25="Да",1,0)*$R$10+IF(M25="Да",1,0)*$R$11+IF(N25="Да",1,0)*$R$12)*IF($R$3="Да",0.5,1) -> 0 | Q25: C/C++ | R25: 1.8 | S25: 2 | T25: 2 - бэкенд
A26: Приложение 25 | C26: =IFERROR(VLOOKUP(B26,Таблица1[#All],2,FALSE),"-") -> - | G26: =IFERROR(VLOOKUP(F26,Таблица3[#All],2,FALSE),"-") -> - | H26: 0 | J26: 0 | K26: Нет | L26: Нет | M26: Нет | N26: Нет | O26: =$R$8*I26*(IF(K26="Да",1,0)*$R$9+IF(L26="Да",1,0)*$R$10+IF(M26="Да",1,0)*$R$11+IF(N26="Да",1,0)*$R$12)*J26*IF($R$3="Да",0.5,1)+$R$8*H26*(IF(K26="Да",1,0)*$R$9+IF(L26="Да",1,0)*$R$10+IF(M26="Да",1,0)*$R$11+IF(N26="Да",1,0)*$R$12)*IF($R$3="Да",0.5,1) -> 0 | Q26: COBOL | R26: 2 | S26: 5 | T26: 5 - мутные языки
A27: Приложение 26 | C27: =IFERROR(VLOOKUP(B27,Таблица1[#All],2,FALSE),"-") -> - | G27: =IFERROR(VLOOKUP(F27,Таблица3[#All],2,FALSE),"-") -> - | H27: 0 | J27: 0 | K27: Нет | L27: Нет | M27: Нет | N27: Нет | O27: =$R$8*I27*(IF(K27="Да",1,0)*$R$9+IF(L27="Да",1,0)*$R$10+IF(M27="Да",1,0)*$R$11+IF(N27="Да",1,0)*$R$12)*J27*IF($R$3="Да",0.5,1)+$R$8*H27*(IF(K27="Да",1,0)*$R$9+IF(L27="Да",1,0)*$R$10+IF(M27="Да",1,0)*$R$11+IF(N27="Да",1,0)*$R$12)*IF($R$3="Да",0.5,1) -> 0 | Q27: Dart | R27: 1.1 | S27: 4 | T27: 4 - мобильная разработка
A28: Приложение 27 | C28: =IFERROR(VLOOKUP(B28,Таблица1[#All],2,FALSE),"-") -> - | G28: =IFERROR(VLOOKUP(F28,Таблица3[#All],2,FALSE),"-") -> - | H28: 0 | J28: 0 | K28: Нет | L28: Нет | M28: Нет | N28: Нет | O28: =$R$8*I28*(IF(K28="Да",1,0)*$R$9+IF(L28="Да",1,0)*$R$10+IF(M28="Да",1,0)*$R$11+IF(N28="Да",1,0)*$R$12)*J28*IF($R$3="Да",0.5,1)+$R$8*H28*(IF(K28="Да",1,0)*$R$9+IF(L28="Да",1,0)*$R$10+IF(M28="Да",1,0)*$R$11+IF(N28="Да",1,0)*$R$12)*IF($R$3="Да",0.5,1) -> 0 | Q28: Delphi | R28: 1 | S28: 2 | T28: 2 - бэкенд
A29: Приложение 28 | C29: =IFERROR(VLOOKUP(B29,Таблица1[#All],2,FALSE),"-") -> - | G29: =IFERROR(VLOOKUP(F29,Таблица3[#All],2,FALSE),"-") -> - | H29: 0 | J29: 0 | K29: Нет | L29: Нет | M29: Нет | N29: Нет | O29: =$R$8*I29*(IF(K29="Да",1,0)*$R$9+IF(L29="Да",1,0)*$R$10+IF(M29="Да",1,0)*$R$11+IF(N29="Да",1,0)*$R$12)*J29*IF($R$3="Да",0.5,1)+$R$8*H29*(IF(K29="Да",1,0)*$R$9+IF(L29="Да",1,0)*$R$10+IF(M29="Да",1,0)*$R$11+IF(N29="Да",1,0)*$R$12)*IF($R$3="Да",0.5,1) -> 0 | Q29: Groovy | R29: 1.1 | S29: 1 | T29: 1 - компилируемые языки
A30: Приложение 29 | C30: =IFERROR(VLOOKUP(B30,Таблица1[#All],2,FALSE),"-") -> - | G30: =IFERROR(VLOOKUP(F30,Таблица3[#All],2,FALSE),"-") -> - | H30: 0 | J30: 0 | K30: Нет | L30: Нет | M30: Нет | N30: Нет | O30: =$R$8*I30*(IF(K30="Да",1,0)*$R$9+IF(L30="Да",1,0)*$R$10+IF(M30="Да",1,0)*$R$11+IF(N30="Да",1,0)*$R$12)*J30*IF($R$3="Да",0.5,1)+$R$8*H30*(IF(K30="Да",1,0)*$R$9+IF(L30="Да",1,0)*$R$10+IF(M30="Да",1,0)*$R$11+IF(N30="Да",1,0)*$R$12)*IF($R$3="Да",0.5,1) -> 0 | Q30: HTML | R30: 1 | S30: 3 | T30: 3 - бэкенд
A31: Приложение 30 | C31: =IFERROR(VLOOKUP(B31,Таблица1[#All],2,FALSE),"-") -> - | G31: =IFERROR(VLOOKUP(F31,Таблица3[#All],2,FALSE),"-") -> - | H31: 0 | J31: 0 | K31: Нет | L31: Нет | M31: Нет | N31: Нет | O31: =$R$8*I31*(IF(K31="Да",1,0)*$R$9+IF(L31="Да",1,0)*$R$10+IF(M31="Да",1,0)*$R$11+IF(N31="Да",1,0)*$R$12)*J31*IF($R$3="Да",0.5,1)+$R$8*H31*(IF(K31="Да",1,0)*$R$9+IF(L31="Да",1,0)*$R$10+IF(M31="Да",1,0)*$R$11+IF(N31="Да",1,0)*$R$12)*IF($R$3="Да",0.5,1) -> 0 | Q31: Kotlin | R31: 1.1 | S31: 1 или 4 | T31: 4 - мобильная разработка
A32: Приложение 31 | C32: =IFERROR(VLOOKUP(B32,Таблица1[#All],2,FALSE),"-") -> - | G32: =IFERROR(VLOOKUP(F32,Таблица3[#All],2,FALSE),"-") -> - | H32: 0 | J32: 0 | K32: Нет | L32: Нет | M32: Нет | N32: Нет | O32: =$R$8*I32*(IF(K32="Да",1,0)*$R$9+IF(L32="Да",1,0)*$R$10+IF(M32="Да",1,0)*$R$11+IF(N32="Да",1,0)*$R$12)*J32*IF($R$3="Да",0.5,1)+$R$8*H32*(IF(K32="Да",1,0)*$R$9+IF(L32="Да",1,0)*$R$10+IF(M32="Да",1,0)*$R$11+IF(N32="Да",1,0)*$R$12)*IF($R$3="Да",0.5,1) -> 0 | Q32: Java | R32: 1.1 | S32: 1 | T32: 1 - компилируемые языки
A33: Приложение 32 | C33: =IFERROR(VLOOKUP(B33,Таблица1[#All],2,FALSE),"-") -> - | G33: =IFERROR(VLOOKUP(F33,Таблица3[#All],2,FALSE),"-") -> - | H33: 0 | J33: 0 | K33: Нет | L33: Нет | M33: Нет | N33: Нет | O33: =$R$8*I33*(IF(K33="Да",1,0)*$R$9+IF(L33="Да",1,0)*$R$10+IF(M33="Да",1,0)*$R$11+IF(N33="Да",1,0)*$R$12)*J33*IF($R$3="Да",0.5,1)+$R$8*H33*(IF(K33="Да",1,0)*$R$9+IF(L33="Да",1,0)*$R$10+IF(M33="Да",1,0)*$R$11+IF(N33="Да",1,0)*$R$12)*IF($R$3="Да",0.5,1) -> 0 | Q33: JavaScript | R33: 1.1 | S33: 3 | T33: 3 - бэкенд
A34: Приложение 33 | C34: =IFERROR(VLOOKUP(B34,Таблица1[#All],2,FALSE),"-") -> - | G34: =IFERROR(VLOOKUP(F34,Таблица3[#All],2,FALSE),"-") -> - | H34: 0 | J34: 0 | K34: Нет | L34: Нет | M34: Нет | N34: Нет | O34: =$R$8*I34*(IF(K34="Да",1,0)*$R$9+IF(L34="Да",1,0)*$R$10+IF(M34="Да",1,0)*$R$11+IF(N34="Да",1,0)*$R$12)*J34*IF($R$3="Да",0.5,1)+$R$8*H34*(IF(K34="Да",1,0)*$R$9+IF(L34="Да",1,0)*$R$10+IF(M34="Да",1,0)*$R$11+IF(N34="Да",1,0)*$R$12)*IF($R$3="Да",0.5,1) -> 0 | Q34: LotusScript | R34: 1.1 | S34: 1 | T34: 1 - компилируемые языки
A35: Приложение 34 | C35: =IFERROR(VLOOKUP(B35,Таблица1[#All],2,FALSE),"-") -> - | G35: =IFERROR(VLOOKUP(F35,Таблица3[#All],2,FALSE),"-") -> - | H35: 0 | J35: 0 | K35: Нет | L35: Нет | M35: Нет | N35: Нет | O35: =$R$8*I35*(IF(K35="Да",1,0)*$R$9+IF(L35="Да",1,0)*$R$10+IF(M35="Да",1,0)*$R$11+IF(N35="Да",1,0)*$R$12)*J35*IF($R$3="Да",0.5,1)+$R$8*H35*(IF(K35="Да",1,0)*$R$9+IF(L35="Да",1,0)*$R$10+IF(M35="Да",1,0)*$R$11+IF(N35="Да",1,0)*$R$12)*IF($R$3="Да",0.5,1) -> 0 | Q35: Objective-C | R35: 1 | S35: 2 | T35: 2 - бэкенд
A36: Приложение 35 | C36: =IFERROR(VLOOKUP(B36,Таблица1[#All],2,FALSE),"-") -> - | G36: =IFERROR(VLOOKUP(F36,Таблица3[#All],2,FALSE),"-") -> - | H36: 0 | J36: 0 | K36: Нет | L36: Нет | M36: Нет | N36: Нет | O36: =$R$8*I36*(IF(K36="Да",1,0)*$R$9+IF(L36="Да",1,0)*$R$10+IF(M36="Да",1,0)*$R$11+IF(N36="Да",1,0)*$R$12)*J36*IF($R$3="Да",0.5,1)+$R$8*H36*(IF(K36="Да",1,0)*$R$9+IF(L36="Да",1,0)*$R$10+IF(M36="Да",1,0)*$R$11+IF(N36="Да",1,0)*$R$12)*IF($R$3="Да",0.5,1) -> 0 | Q36: Pascal | R36: 1 | S36: 2 | T36: 2 - бэкенд
A37: Приложение 36 | C37: =IFERROR(VLOOKUP(B37,Таблица1[#All],2,FALSE),"-") -> - | G37: =IFERROR(VLOOKUP(F37,Таблица3[#All],2,FALSE),"-") -> - | H37: 0 | J37: 0 | K37: Нет | L37: Нет | M37: Нет | N37: Нет | O37: =$R$8*I37*(IF(K37="Да",1,0)*$R$9+IF(L37="Да",1,0)*$R$10+IF(M37="Да",1,0)*$R$11+IF(N37="Да",1,0)*$R$12)*J37*IF($R$3="Да",0.5,1)+$R$8*H37*(IF(K37="Да",1,0)*$R$9+IF(L37="Да",1,0)*$R$10+IF(M37="Да",1,0)*$R$11+IF(N37="Да",1,0)*$R$12)*IF($R$3="Да",0.5,1) -> 0 | Q37: PHP | R37: 1 | S37: 3 | T37: 3 - бэкенд
A38: Приложение 37 | C38: =IFERROR(VLOOKUP(B38,Таблица1[#All],2,FALSE),"-") -> - | G38: =IFERROR(VLOOKUP(F38,Таблица3[#All],2,FALSE),"-") -> - | H38: 0 | J38: 0 | K38: Нет | L38: Нет | M38: Нет | N38: Нет | O38: =$R$8*I38*(IF(K38="Да",1,0)*$R$9+IF(L38="Да",1,0)*$R$10+IF(M38="Да",1,0)*$R$11+IF(N38="Да",1,0)*$R$12)*J38*IF($R$3="Да",0.5,1)+$R$8*H38*(IF(K38="Да",1,0)*$R$9+IF(L38="Да",1,0)*$R$10+IF(M38="Да",1,0)*$R$11+IF(N38="Да",1,0)*$R$12)*IF($R$3="Да",0.5,1) -> 0 | Q38: PL/SQL | R38: 1.1 | S38: 2 или 3 | T38: 2 - бэкенд, 3 - тоже бэкенд
A39: Приложение 38 | C39: =IFERROR(VLOOKUP(B39,Таблица1[#All],2,FALSE),"-") -> - | G39: =IFERROR(VLOOKUP(F39,Таблица3[#All],2,FALSE),"-") -> - | H39: 0 | J39: 0 | K39: Нет | L39: Нет | M39: Нет | N39: Нет | O39: =$R$8*I39*(IF(K39="Да",1,0)*$R$9+IF(L39="Да",1,0)*$R$10+IF(M39="Да",1,0)*$R$11+IF(N39="Да",1,0)*$R$12)*J39*IF($R$3="Да",0.5,1)+$R$8*H39*(IF(K39="Да",1,0)*$R$9+IF(L39="Да",1,0)*$R$10+IF(M39="Да",1,0)*$R$11+IF(N39="Да",1,0)*$R$12)*IF($R$3="Да",0.5,1) -> 0 | Q39: Perl | R39: 1.1 | S39: 3 | T39: 3 - бэкенд
A40: Приложение 39 | C40: =IFERROR(VLOOKUP(B40,Таблица1[#All],2,FALSE),"-") -> - | G40: =IFERROR(VLOOKUP(F40,Таблица3[#All],2,FALSE),"-") -> - | H40: 0 | J40: 0 | K40: Нет | L40: Нет | M40: Нет | N40: Нет | O40: =$R$8*I40*(IF(K40="Да",1,0)*$R$9+IF(L40="Да",1,0)*$R$10+IF(M40="Да",1,0)*$R$11+IF(N40="Да",1,0)*$R$12)*J40*IF($R$3="Да",0.5,1)+$R$8*H40*(IF(K40="Да",1,0)*$R$9+IF(L40="Да",1,0)*$R$10+IF(M40="Да",1,0)*$R$11+IF(N40="Да",1,0)*$R$12)*IF($R$3="Да",0.5,1) -> 0 | Q40: Ruby | R40: 1.1 | S40: 1 | T40: 1 - компилируемые языки
...

Sheet Расчет FTE DSO
A1: Задача | B1: Единица измерения | C1: Норма времени (в часах) | D1: Периодичность выполнения | E1: Выполняется несколько раз в неделю | F1: Выполняется несколько раз в месяц | G1: Выполняется несколько раз в квартал | H1: Итого в год, часов
A2: ПРИМЕР!
A3: Container security
A4: 1. Контроль корректности текущих настроек и конфигурации | J4: Параметр | K4: Значение
